<?xml version="1.0" encoding="utf-8"?>
<!-- This URDF was automatically created by SolidWorks to URDF Exporter! Originally created by Stephen Brawner (brawner@gmail.com) 
     Commit Version: 1.6.0-4-g7f85cfe  Build Version: 1.6.7995.38578
     For more information, please see http://wiki.ros.org/sw_urdf_exporter -->
<robot
  name="paeallel gripper">
  <link
    name="base_link">
    <inertial>
      <origin
        xyz="-0.000443252122602931 -0.000442763662401773 -0.0789823429237976"
        rpy="0 0 0" />
      <mass
        value="0.449990387701698" />
      <inertia
        ixx="0.000611599768651393"
        ixy="0.000109863285594623"
        ixz="-1.94162169945949E-06"
        iyy="0.000611597595039472"
        iyz="-1.94141723807738E-06"
        izz="0.000708132649475118" />
    </inertial>
    <visual>
      <origin
        xyz="0 0 0"
        rpy="0 0 0" />
      <geometry>
        <mesh
          filename="package://paeallel gripper/meshes/base_link.STL" />
      </geometry>
      <material
        name="">
        <color
          rgba="0.698039215686274 0.698039215686274 0.698039215686274 1" />
      </material>
    </visual>
    <collision>
      <origin
        xyz="0 0 0"
        rpy="0 0 0" />
      <geometry>
        <mesh
          filename="package://paeallel gripper/meshes/base_link.STL" />
      </geometry>
    </collision>
  </link>
  <link
    name="motor">
    <inertial>
      <origin
        xyz="9.22590686407531E-05 -0.0001677011502331 -0.0090821453339556"
        rpy="0 0 0" />
      <mass
        value="0.128244907778305" />
      <inertia
        ixx="1.4145663490098E-05"
        ixy="-1.07192889077197E-05"
        ixz="3.80937341211656E-10"
        iyy="2.75049357553638E-05"
        iyz="-6.92422845600556E-10"
        izz="3.19913265885044E-05" />
    </inertial>
    <visual>
      <origin
        xyz="0 0 0"
        rpy="0 0 0" />
      <geometry>
        <mesh
          filename="package://paeallel gripper/meshes/motor.STL" />
      </geometry>
      <material
        name="">
        <color
          rgba="0.698039215686274 0.698039215686274 0.698039215686274 1" />
      </material>
    </visual>
    <collision>
      <origin
        xyz="0 0 0"
        rpy="0 0 0" />
      <geometry>
        <mesh
          filename="package://paeallel gripper/meshes/motor.STL" />
      </geometry>
    </collision>
  </link>
  <joint
    name="motor"
    type="revolute">
    <origin
      xyz="0 0 -0.146000000000002"
      rpy="0 0 0" />
    <parent
      link="base_link" />
    <child
      link="motor" />
    <axis
      xyz="0 0 -1" />
    <limit
      lower="0"
      upper="0.9601618283"
      effort="0"
      velocity="0" />
  </joint>
  <link
    name="link1">
    <inertial>
      <origin
        xyz="-0.0298586239548906 0.0197261040508656 -0.0036142199354076"
        rpy="0 0 0" />
      <mass
        value="0.00248577770480401" />
      <inertia
        ixx="5.61968001929898E-08"
        ixy="4.67872105961216E-08"
        ixz="9.55423899712618E-16"
        iyy="9.61069133377032E-08"
        iyz="-6.13446905808832E-16"
        izz="1.26527926465619E-07" />
    </inertial>
    <visual>
      <origin
        xyz="0 0 0"
        rpy="0 0 0" />
      <geometry>
        <mesh
          filename="package://paeallel gripper/meshes/link1.STL" />
      </geometry>
      <material
        name="">
        <color
          rgba="0.501960784313725 0.501960784313725 0.501960784313725 1" />
      </material>
    </visual>
    <collision>
      <origin
        xyz="0 0 0"
        rpy="0 0 0" />
      <geometry>
        <mesh
          filename="package://paeallel gripper/meshes/link1.STL" />
      </geometry>
    </collision>
  </link>
  <joint
    name="link1"
    type="revolute">
    <origin
      xyz="0.021614 0.022952 -0.0075"
      rpy="0 0 0" />
    <parent
      link="motor" />
    <child
      link="link1" />
    <axis
      xyz="0 0 -1" />
    <limit
      lower="-3.14"
      upper="3.14"
      effort="0"
      velocity="0" />
    <mimic
      joint="motor"
      multiplier="-0.88"
      offset="0" />
  </joint>
  <link
    name="link2">
    <inertial>
      <origin
        xyz="0.0299689669230293 -0.0195580578819348 -0.00361422009657247"
        rpy="0 0 0" />
      <mass
        value="0.00248577769066908" />
      <inertia
        ixx="5.5672399023117E-08"
        ixy="4.65600605113971E-08"
        ixz="1.29551524737056E-20"
        iyy="9.66313146049496E-08"
        iyz="-6.81212621467356E-21"
        izz="1.26527926643365E-07" />
    </inertial>
    <visual>
      <origin
        xyz="0 0 0"
        rpy="0 0 0" />
      <geometry>
        <mesh
          filename="package://paeallel gripper/meshes/link2.STL" />
      </geometry>
      <material
        name="">
        <color
          rgba="0.501960784313725 0.501960784313725 0.501960784313725 1" />
      </material>
    </visual>
    <collision>
      <origin
        xyz="0 0 0"
        rpy="0 0 0" />
      <geometry>
        <mesh
          filename="package://paeallel gripper/meshes/link2.STL" />
      </geometry>
    </collision>
  </link>
  <joint
    name="link2"
    type="revolute">
    <origin
      xyz="-0.021316 -0.023492 -0.007"
      rpy="0 0 0" />
    <parent
      link="motor" />
    <child
      link="link2" />
    <axis
      xyz="0 0 -1" />
    <limit
      lower="-3.14"
      upper="3.14"
      effort="0"
      velocity="0" />
    <mimic
      joint="motor"
      multiplier="-0.88"
      offset="0" />
  </joint>
  <link
    name="p1">
    <inertial>
      <origin
        xyz="-0.0251576655127445 0.0270743349939394 0.0471197404654572"
        rpy="0 0 0" />
      <mass
        value="0.0639216206656708" />
      <inertia
        ixx="3.46401729832417E-05"
        ixy="1.73539659004351E-06"
        ixz="6.38448685760896E-06"
        iyy="3.46401741707637E-05"
        iyz="-6.74759673488215E-06"
        izz="1.17759934604075E-05" />
    </inertial>
    <visual>
      <origin
        xyz="0 0 0"
        rpy="0 0 0" />
      <geometry>
        <mesh
          filename="package://paeallel gripper/meshes/p1.STL" />
      </geometry>
      <material
        name="">
        <color
          rgba="0.698039215686274 0.698039215686274 0.698039215686274 1" />
      </material>
    </visual>
    <collision>
      <origin
        xyz="0 0 0"
        rpy="0 0 0" />
      <geometry>
        <mesh
          filename="package://paeallel gripper/meshes/p1.STL" />
      </geometry>
    </collision>
  </link>
  <joint
    name="p1"
    type="prismatic">
    <origin
      xyz="-0.017452 0.017593 -0.25991"
      rpy="0 0 0" />
    <parent
      link="base_link" />
    <child
      link="p1" />
    <axis
      xyz="-0.70711 0.70711 0" />
    <limit
      lower="-0.02554"
      upper="0"
      effort="0"
      velocity="0" />
    <mimic
      joint="motor"
      multiplier="-0.0265996827277"
      offset="0" />
  </joint>
  <link
    name="p2">
    <inertial>
      <origin
        xyz="0.025157665509298 -0.0270743349973465 0.0471197404654611"
        rpy="0 0 0" />
      <mass
        value="0.0639216206656709" />
      <inertia
        ixx="3.46401729832416E-05"
        ixy="1.73539659004246E-06"
        ixz="-6.38448685708194E-06"
        iyy="3.46401741707663E-05"
        iyz="6.74759673534727E-06"
        izz="1.17759934604052E-05" />
    </inertial>
    <visual>
      <origin
        xyz="0 0 0"
        rpy="0 0 0" />
      <geometry>
        <mesh
          filename="package://paeallel gripper/meshes/p2.STL" />
      </geometry>
      <material
        name="">
        <color
          rgba="0.698039215686274 0.698039215686274 0.698039215686274 1" />
      </material>
    </visual>
    <collision>
      <origin
        xyz="0 0 0"
        rpy="0 0 0" />
      <geometry>
        <mesh
          filename="package://paeallel gripper/meshes/p2.STL" />
      </geometry>
    </collision>
  </link>
  <joint
    name="p2"
    type="prismatic">
    <origin
      xyz="0.01795 -0.017808 -0.25991"
      rpy="0 0 0" />
    <parent
      link="base_link" />
    <child
      link="p2" />
    <axis
      xyz="0.70711 -0.70711 0" />
    <limit
      lower="-0.02554"
      upper="0"
      effort="0"
      velocity="0" />
    <mimic
      joint="motor"
      multiplier="-0.0265996827277"
      offset="0" />
  </joint>
</robot>